<sdf version='1.9'>
  <world name='default'>
  <physics name="1ms" type="ignored">
      <max_step_size>0.001</max_step_size>
      <real_time_factor>1.0</real_time_factor>
  </physics>
  <plugin
      filename="ignition-gazebo-physics-system"
      name="ignition::gazebo::systems::Physics">
  </plugin>
  <plugin
      filename="ignition-gazebo-user-commands-system"
      name="ignition::gazebo::systems::UserCommands">
  </plugin>
  <plugin
      filename="ignition-gazebo-scene-broadcaster-system"
      name="ignition::gazebo::systems::SceneBroadcaster">
  </plugin>
  <plugin filename="libignition-gazebo-contact-system.so"
          name="ignition::gazebo::systems::Contact">
  </plugin>
  <plugin filename="libignition-gazebo-imu-system.so"
          name="ignition::gazebo::systems::Imu">
  </plugin>
  <plugin
      filename="libignition-gazebo-sensors-system.so"
      name="ignition::gazebo::systems::Sensors">
      <render_engine>ogre2</render_engine>
  </plugin>
  
    <model name='terrain'>
      <static>true</static>
      <pose>1 -1 -1.5 0 0 0</pose>
      <link name='terrain_surface'>
        <collision name='collision'>
          <geometry>
            <mesh>
              <uri>surface1.stl</uri>
            </mesh>
          </geometry>
          <surface>
            <friction>
              <ode>
                <mu>100</mu>
                <mu2>50</mu2>
              </ode>
            </friction>
          </surface>
        </collision>
        <visual name='visual'>
          <cast_shadows>false</cast_shadows>
          <geometry>
            <mesh>
              <uri>surface1.stl</uri>
            </mesh>
          </geometry>
          <material>
              <diffuse>0.54 0.27 0.07 1</diffuse>
              <ambient>0.2 0.2 0.2 1</ambient>
          </material>
        </visual>
      </link>
    </model>
    <gravity>0 0 -9.8</gravity>
    <magnetic_field>6e-06 2.3e-05 -4.2e-05</magnetic_field>
    <atmosphere type='adiabatic'/>
    <physics type='ode'>
      <max_step_size>0.001</max_step_size>
      <real_time_factor>1</real_time_factor>
      <real_time_update_rate>1000</real_time_update_rate>
    </physics>
    <scene>
      <ambient>0.4 0.4 0.4 1</ambient>
      <background>0.7 0.7 0.7 1</background>
      <shadows>true</shadows>
    </scene>

    <light type="directional" name="sun">
    <cast_shadows>true</cast_shadows>
    <pose>0 0 10 0 0 0</pose>
    <diffuse>0.8 0.8 0.8 1</diffuse>
    <specular>0.2 0.2 0.2 1</specular>
    <attenuation>
        <range>1000</range>
        <constant>0.9</constant>
        <linear>0.01</linear>
        <quadratic>0.001</quadratic>
    </attenuation>
    <direction>-0.5 0.1 -0.9</direction>
    </light>


    <model name='mars_rover'>
    <link name='base_rover_1'>
      <inertial>
        <pose>0 0 0 0 0 0</pose>
        <mass>2.7999999999999998</mass>
        <inertia>
          <ixx>0.195684</ixx>
          <ixy>0</ixy>
          <ixz>0</ixz>
          <iyy>0.1</iyy>
          <iyz>0</iyz>
          <izz>0.14455</izz>
        </inertia>
      </inertial>
      <collision name='base_rover_1_collision'>
        <pose>0 0 0 0 0 0</pose>
        <geometry>
          <mesh>
            <scale>1 1 1</scale>
            <uri>../meshes/base_rover_1.STL</uri>
          </mesh>
        </geometry>
      </collision>
      <visual name='base_rover_1_visual'>
        <pose>0 0 0 0 0 0</pose>
        <geometry>
          <mesh>
            <scale>1 1 1</scale>
            <uri>../meshes/base_rover_1.STL</uri>
          </mesh>
        </geometry>
        <material>
          <diffuse>0.990196 1 1 1</diffuse>
          <ambient>0.990196 1 1 1</ambient>
        </material>
      </visual>
      <sensor name='real_color' type='camera'>
        <camera name='real_camera'>
          <horizontal_fov>1.0469999999999999</horizontal_fov>
          <image>
            <width>640</width>
            <height>480</height>
            <format>RGB_INT8</format>
          </image>
          <clip>
            <near>0.10000000000000001</near>
            <far>100</far>
          </clip>
          <noise>
            <type>gaussian</type>
            <mean>0</mean>
            <stddev>0.0070000000000000001</stddev>
          </noise>
        </camera>
        <always_on>true</always_on>
        <update_rate>30</update_rate>
        <visualize>true</visualize>
        <pose>0.5 -0.896 0.504 0 -0 0</pose>
      </sensor>
      <sensor name='real_depth' type='depth'>
        <camera name='real_camera'>
          <horizontal_fov>1.0469999999999999</horizontal_fov>
          <image>
            <width>640</width>
            <height>480</height>
            <format>L_INT16</format>
          </image>
          <clip>
            <near>0.10000000000000001</near>
            <far>100</far>
          </clip>
          <noise>
            <type>gaussian</type>
            <mean>0</mean>
            <stddev>0</stddev>
          </noise>
        </camera>
        <always_on>true</always_on>
        <update_rate>30</update_rate>
        <visualize>false</visualize>
        <pose>0.5 -0.88 0.504 0 -0 0</pose>
      </sensor>
      <sensor name='real_infrared1' type='camera'>
        <camera name='real_camera'>
          <horizontal_fov>1.0469999999999999</horizontal_fov>
          <image>
            <width>640</width>
            <height>480</height>
            <format>L_INT8</format>
          </image>
          <clip>
            <near>0.10000000000000001</near>
            <far>100</far>
          </clip>
          <noise>
            <type>gaussian</type>
            <mean>0</mean>
            <stddev>0.050000000000000003</stddev>
          </noise>
        </camera>
        <always_on>true</always_on>
        <update_rate>30</update_rate>
        <visualize>false</visualize>
        <pose>0.5 -0.91 0.504 0 -0 0</pose>
      </sensor>
      <sensor name='real_infrared2' type='camera'>
        <camera name='real_camera'>
          <horizontal_fov>1.0469999999999999</horizontal_fov>
          <image>
            <width>640</width>
            <height>480</height>
            <format>L_INT8</format>
          </image>
          <clip>
            <near>0.10000000000000001</near>
            <far>100</far>
          </clip>
          <noise>
            <type>gaussian</type>
            <mean>0</mean>
            <stddev>0.050000000000000003</stddev>
          </noise>
        </camera>
        <always_on>true</always_on>
        <update_rate>30</update_rate>
        <visualize>false</visualize>
        <pose>0.5 -0.84 0.504 0 -0 0</pose>
      </sensor>
      <gravity>true</gravity>
      <sensor name='imu_sensor' type='imu'>
        <always_on>true</always_on>
        <update_rate>100</update_rate>
        <visualize>true</visualize>
        <topic>__default_topic__</topic>
        <plugin name='imu_plugin' filename='libgazebo_ros_imu_sensor.so'>
          <topicName>imu</topicName>
          <bodyName>imu_link</bodyName>
          <updateRateHZ>10.0</updateRateHZ>
          <gaussianNoise>0.0</gaussianNoise>
          <xyzOffset>0 0 0</xyzOffset>
          <rpyOffset>0 0 0</rpyOffset>
          <frameName>imu_link</frameName>
          <initialOrientationAsReference>false</initialOrientationAsReference>
        </plugin>
        <pose>0.5 -0.85 0.5 0 -0 0</pose>
      </sensor>
    </link>
    <joint name='joint_w1' type='revolute'>
      <pose relative_to='base_rover_1'>0.373705519949924 -0.333276944984588 -0.0128821732436576 -2.57071455235077 -5.551115123125783e-17 1.5707963267949</pose>
      <parent>base_rover_1</parent>
      <child>wheel_1</child>
      <axis>
        <xyz>1 0 0</xyz>
        <limit>
          <lower>-10000000000000000</lower>
          <upper>10000000000000000</upper>
        </limit>
        <dynamics>
          <spring_reference>0</spring_reference>
          <spring_stiffness>0</spring_stiffness>
        </dynamics>
      </axis>
    </joint>
    <link name='wheel_1'>
      <pose relative_to='joint_w1'>0 0 0 0 0 0</pose>
      <inertial>
        <pose>-0.063397 -4.4964e-15 1.4988e-15 0 0 0</pose>
        <mass>6.4992999999999999</mass>
        <inertia>
          <ixx>0.062323999999999997</ixx>
          <ixy>4.8469000000000003e-07</ixy>
          <ixz>-1.0586999999999999e-06</ixz>
          <iyy>0.037900999999999997</iyy>
          <iyz>6.9388999999999993e-18</iyz>
          <izz>0.037900999999999997</izz>
        </inertia>
      </inertial>
      <collision name='wheel_1_collision'>
        <pose>0 0 0 0 0 0</pose>
        <geometry>
          <mesh>
            <scale>1 1 1</scale>
            <uri>../meshes/wheel_1.STL</uri>
          </mesh>
        </geometry>
      </collision>
      <visual name='wheel_1_visual'>
        <pose>0 0 0 0 0 0</pose>
        <geometry>
          <mesh>
            <scale>1 1 1</scale>
            <uri>../meshes/wheel_1.STL</uri>
          </mesh>
        </geometry>
        <material>
          <diffuse>0.9902 1 1 1</diffuse>
          <ambient>0.9902 1 1 1</ambient>
        </material>
      </visual>
    </link>
    <joint name='joint_w2' type='revolute'>
      <pose relative_to='base_rover_1'>-0.0882727119071309 -0.333276944984562 -0.0481207258492364 -0.04857241664653151 0 1.57079632750354</pose>
      <parent>base_rover_1</parent>
      <child>wheel_2</child>
      <axis>
        <xyz>1 0 0</xyz>
        <limit>
          <lower>-10000000000000000</lower>
          <upper>10000000000000000</upper>
        </limit>
        <dynamics>
          <spring_reference>0</spring_reference>
          <spring_stiffness>0</spring_stiffness>
        </dynamics>
      </axis>
    </joint>
    <link name='wheel_2'>
      <pose relative_to='joint_w2'>0 0 0 0 0 0</pose>
      <inertial>
        <pose>-0.063397 3.9968e-15 9.253e-10 0 0 0</pose>
        <mass>6.4992999999999999</mass>
        <inertia>
          <ixx>0.062323999999999997</ixx>
          <ixy>-1.1644e-06</ixy>
          <ixz>-6.9653999999999995e-10</ixz>
          <iyy>0.037900999999999997</iyy>
          <iyz>1.6994000000000001e-14</iyz>
          <izz>0.037900999999999997</izz>
        </inertia>
      </inertial>
      <collision name='wheel_2_collision'>
        <pose>0 0 0 0 0 0</pose>
        <geometry>
          <mesh>
            <scale>1 1 1</scale>
            <uri>../meshes/wheel_2.STL</uri>
          </mesh>
        </geometry>
      </collision>
      <visual name='wheel_2_visual'>
        <pose>0 0 0 0 0 0</pose>
        <geometry>
          <mesh>
            <scale>1 1 1</scale>
            <uri>../meshes/wheel_2.STL</uri>
          </mesh>
        </geometry>
        <material>
          <diffuse>0.9902 1 1 1</diffuse>
          <ambient>0.9902 1 1 1</ambient>
        </material>
      </visual>
    </link>
    <joint name='joint_w3' type='revolute'>
      <pose relative_to='base_rover_1'>-0.441256611089257 -0.333276944984561 -0.0514922118987491 1.5707963267949 -5.551115123125783e-17 1.5707963267949</pose>
      <parent>base_rover_1</parent>
      <child>wheel_3</child>
      <axis>
        <xyz>1 0 0</xyz>
        <limit>
          <lower>-10000000000000000</lower>
          <upper>10000000000000000</upper>
        </limit>
        <dynamics>
          <spring_reference>0</spring_reference>
          <spring_stiffness>0</spring_stiffness>
        </dynamics>
      </axis>
    </joint>
    <link name='wheel_3'>
      <pose relative_to='joint_w3'>0 0 0 0 0 0</pose>
      <inertial>
        <pose>-0.063397 1.9467e-13 -1.3256e-13 0 0 0</pose>
        <mass>6.4992999999999999</mass>
        <inertia>
          <ixx>0.062323999999999997</ixx>
          <ixy>-1.1644e-06</ixy>
          <ixz>-3.4009000000000001e-10</ixz>
          <iyy>0.037900999999999997</iyy>
          <iyz>2.1248999999999999e-20</iyz>
          <izz>0.037900999999999997</izz>
        </inertia>
      </inertial>
      <collision name='wheel_3_collision'>
        <pose>0 0 0 0 0 0</pose>
        <geometry>
          <mesh>
            <scale>1 1 1</scale>
            <uri>../meshes/wheel_3.STL</uri>
          </mesh>
        </geometry>
      </collision>
      <visual name='wheel_3_visual'>
        <pose>0 0 0 0 0 0</pose>
        <geometry>
          <mesh>
            <scale>1 1 1</scale>
            <uri>../meshes/wheel_3.STL</uri>
          </mesh>
        </geometry>
        <material>
          <diffuse>0.9902 1 1 1</diffuse>
          <ambient>0.9902 1 1 1</ambient>
        </material>
      </visual>
    </link>
    <joint name='joint_w4' type='revolute'>
      <pose relative_to='base_rover_1'>0.349142456408795 -1.29967694498458 -0.0366791162624158 -1.96389113722142 0 -1.5707963267949</pose>
      <parent>base_rover_1</parent>
      <child>wheel_4</child>
      <axis>
        <xyz>-1 0 0</xyz>
        <limit>
          <lower>-10000000000000000</lower>
          <upper>10000000000000000</upper>
        </limit>
        <dynamics>
          <spring_reference>0</spring_reference>
          <spring_stiffness>0</spring_stiffness>
        </dynamics>
      </axis>
    </joint>
    <link name='wheel_4'>
      <pose relative_to='joint_w4'>0 0 0 0 0 0</pose>
      <inertial>
        <pose>0.060603 -1.3294e-13 -3.9635e-14 0 0 0</pose>
        <mass>6.4992999999999999</mass>
        <inertia>
          <ixx>0.062323999999999997</ixx>
          <ixy>8.2244999999999996e-07</ixy>
          <ixz>8.2424000000000003e-07</ixz>
          <iyy>0.037900999999999997</iyy>
          <iyz>-2.6020999999999998e-18</iyz>
          <izz>0.037900999999999997</izz>
        </inertia>
      </inertial>
      <collision name='wheel_4_collision'>
        <pose>0 0 0 0 0 0</pose>
        <geometry>
          <mesh>
            <scale>1 1 1</scale>
            <uri>../meshes/wheel_4.STL</uri>
          </mesh>
        </geometry>
      </collision>
      <visual name='wheel_4_visual'>
        <pose>0 0 0 0 0 0</pose>
        <geometry>
          <mesh>
            <scale>1 1 1</scale>
            <uri>../meshes/wheel_4.STL</uri>
          </mesh>
        </geometry>
        <material>
          <diffuse>0.9902 1 1 1</diffuse>
          <ambient>0.9902 1 1 1</ambient>
        </material>
      </visual>
    </link>
    <joint name='joint_w5' type='revolute'>
      <pose relative_to='base_rover_1'>-0.08568653656987631 -1.29967694498458 -0.00527252429838212 -1.96389113722143 -5.551115123125783e-17 -1.5707963267949</pose>
      <parent>base_rover_1</parent>
      <child>wheel_5</child>
      <axis>
        <xyz>-1 0 0</xyz>
        <limit>
          <lower>-10000000000000000</lower>
          <upper>10000000000000000</upper>
        </limit>
        <dynamics>
          <spring_reference>0</spring_reference>
          <spring_stiffness>0</spring_stiffness>
        </dynamics>
      </axis>
    </joint>
    <link name='wheel_5'>
      <pose relative_to='joint_w5'>0 0 0 0 0 0</pose>
      <inertial>
        <pose>0.060603 2.1788e-14 1.6598e-14 0 0 0</pose>
        <mass>6.4992999999999999</mass>
        <inertia>
          <ixx>0.062323999999999997</ixx>
          <ixy>8.2244999999999996e-07</ixy>
          <ixz>8.2424000000000003e-07</ixz>
          <iyy>0.037900999999999997</iyy>
          <iyz>-8.6735999999999998e-19</iyz>
          <izz>0.037900999999999997</izz>
        </inertia>
      </inertial>
      <collision name='wheel_5_collision'>
        <pose>0 0 0 0 0 0</pose>
        <geometry>
          <mesh>
            <scale>1 1 1</scale>
            <uri>../meshes/wheel_5.STL</uri>
          </mesh>
        </geometry>
      </collision>
      <visual name='wheel_5_visual'>
        <pose>0 0 0 0 0 0</pose>
        <geometry>
          <mesh>
            <scale>1 1 1</scale>
            <uri>../meshes/wheel_5.STL</uri>
          </mesh>
        </geometry>
        <material>
          <diffuse>0.9902 1 1 1</diffuse>
          <ambient>0.9902 1 1 1</ambient>
        </material>
      </visual>
    </link>
    <joint name='joint_w6' type='revolute'>
      <pose relative_to='base_rover_1'>-0.436966864880414 -1.29967694498458 -0.0400738309123618 -1.96389113722143 -5.551115123125783e-17 -1.5707963267949</pose>
      <parent>base_rover_1</parent>
      <child>wheel_6</child>
      <axis>
        <xyz>-1 0 0</xyz>
        <limit>
          <lower>-10000000000000000</lower>
          <upper>10000000000000000</upper>
        </limit>
        <dynamics>
          <spring_reference>0</spring_reference>
          <spring_stiffness>0</spring_stiffness>
        </dynamics>
      </axis>
    </joint>
    <link name='wheel_6'>
      <pose relative_to='joint_w6'>0 0 0 0 0 0</pose>
      <inertial>
        <pose>0.060603 1.4413e-13 8.2656e-14 0 0 0</pose>
        <mass>6.4992999999999999</mass>
        <inertia>
          <ixx>0.062323999999999997</ixx>
          <ixy>8.2244999999999996e-07</ixy>
          <ixz>8.2424000000000003e-07</ixz>
          <iyy>0.037900999999999997</iyy>
          <iyz>-3.4693999999999998e-18</iyz>
          <izz>0.037900999999999997</izz>
        </inertia>
      </inertial>
      <collision name='wheel_6_collision'>
        <pose>0 0 0 0 0 0</pose>
        <geometry>
          <mesh>
            <scale>1 1 1</scale>
            <uri>../meshes/wheel_6.STL</uri>
          </mesh>
        </geometry>
      </collision>
      <visual name='wheel_6_visual'>
        <pose>0 0 0 0 0 0</pose>
        <geometry>
          <mesh>
            <scale>1 1 1</scale>
            <uri>../meshes/wheel_6.STL</uri>
          </mesh>
        </geometry>
        <material>
          <diffuse>0.9902 1 1 1</diffuse>
          <ambient>0.9902 1 1 1</ambient>
        </material>
      </visual>
    </link>
    
    <plugin
            filename="libignition-gazebo-diff-drive-system.so"
            name="ignition::gazebo::systems::DiffDrive">
            <left_joint>joint_w1</left_joint>
            <right_joint>joint_w4</right_joint>
            <left_joint>joint_w2</left_joint>
            <right_joint>joint_w5</right_joint>
            <left_joint>joint_w2</left_joint>
            <right_joint>joint_w6</right_joint>
            <wheel_separation>0.9634</wheel_separation>
            <wheel_radius>0.1425</wheel_radius>
            <odom_publish_frequency>1</odom_publish_frequency>
            <topic>cmd_vel</topic>
    </plugin>

    <plugin name='gazebo_ros_gps' filename='libhector_gazebo_ros_gps.so'>
      <updateRate>10.0</updateRate>
      <bodyName>base_rover_1</bodyName>
      <frameId>base_rover_1</frameId>
      <topicName>/gps/fix</topicName>
      <velocityTopicName>/gps/fix_velocity</velocityTopicName>
      <referenceLatitude>31.7754</referenceLatitude>
      <referenceLongitude>76.9861</referenceLongitude>
      <referenceHeading>20</referenceHeading>
      <referenceAltitude>10</referenceAltitude>
      <offset>0 0 0</offset>
      <drift>0 0 0</drift>
      <gaussianNoise>0.05 0.05 0.05</gaussianNoise>
      <velocityDrift>0.0001 0.0001 0.0001</velocityDrift>
      <velocityGaussianNoise>0.5 0.5 0.5</velocityGaussianNoise>
    </plugin>
    <plugin name='real_d435' filename='librealsense_gazebo_plugin.so'>
      <colorTopicName>/camera/color/image_raw</colorTopicName>
      <colorCameraInfoTopicName>/camera/color/camera_info</colorCameraInfoTopicName>
      <depthTopicName>/camera/depth/image_raw</depthTopicName>
      <depthCameraInfoTopicName>/camera/depth/camera_info</depthCameraInfoTopicName>
      <infrared1TopicName>/camera/depth/image_raw</infrared1TopicName>
      <infrared1CameraInfoTopicName>/camera/depth/camera_info</infrared1CameraInfoTopicName>
      <infrared2TopicName>/camera/depth/image_raw</infrared2TopicName>
      <infrared2CameraInfoTopicName>/camera/depth/camera_info</infrared2CameraInfoTopicName>
      <pointCloudTopicName>/camera/depth/points</pointCloudTopicName>
      <colorOpticalframeName>base_depth</colorOpticalframeName>
      <depthOpticalframeName>base_depth</depthOpticalframeName>
      <infrared1OpticalframeName>base_depth</infrared1OpticalframeName>
      <infrared2OpticalframeName>base_depth</infrared2OpticalframeName>
      <robotNamespace/>
    </plugin>
    <!-- <plugin name='gazebo_ros_control' filename='libgazebo_ros_control.so'>
      <robotNamespace>/</robotNamespace>
      <legacyModeNS>true</legacyModeNS>
    </plugin> -->
    <frame name='depth_joint' attached_to='base_rover_1'>
      <pose>0.5 -0.85 0.5 0 -0 0</pose>
    </frame>
    <frame name='base_depth' attached_to='depth_joint'/>
    <frame name='imu_joint' attached_to='base_rover_1'>
      <pose>0.5 -0.85 0.5 0 -0 0</pose>
    </frame>
    <frame name='imu_link' attached_to='imu_joint'/>
  </model>

  <!-- Moving Forward-->
        <plugin filename="libignition-gazebo-triggered-publisher-system.so"
                name="ignition::gazebo::systems::TriggeredPublisher">
            <input type="ignition.msgs.Int32" topic="/keyboard/keypress">
                <match field="data">16777235</match>
            </input>
            <output type="ignition.msgs.Twist" topic="/cmd_vel">
                linear: {x: 0.5}, angular: {z: 0.0}
            </output>
        </plugin>

        <!-- Moving Backward-->
        <plugin filename="libignition-gazebo-triggered-publisher-system.so"
                name="ignition::gazebo::systems::TriggeredPublisher">
            <input type="ignition.msgs.Int32" topic="/keyboard/keypress">
                <match field="data">16777237</match>
            </input>
            <output type="ignition.msgs.Twist" topic="/cmd_vel">
                linear: {x: -0.5}, angular: {z: 0.0}
            </output>
        </plugin>

        <!-- Moving Left-->
        <plugin filename="libignition-gazebo-triggered-publisher-system.so"
                name="ignition::gazebo::systems::TriggeredPublisher">
            <input type="ignition.msgs.Int32" topic="/keyboard/keypress">
                <match field="data">16777234</match>
            </input>
            <output type="ignition.msgs.Twist" topic="/cmd_vel">
                linear: {x: 0.0}, angular: {z: 0.5}
            </output>
        </plugin>

        <!-- Moving Right-->
        <plugin filename="libignition-gazebo-triggered-publisher-system.so"
                name="ignition::gazebo::systems::TriggeredPublisher">
            <input type="ignition.msgs.Int32" topic="/keyboard/keypress">
                <match field="data">16777236</match>
            </input>
            <output type="ignition.msgs.Twist" topic="/cmd_vel">
                linear: {x: 0.0}, angular: {z: -0.5}
            </output>
        </plugin>

        <!-- Stop-->
        <plugin filename="libignition-gazebo-triggered-publisher-system.so"
                name="ignition::gazebo::systems::TriggeredPublisher">
            <input type="ignition.msgs.Int32" topic="/keyboard/keypress">
                <match field="data">80</match>
            </input>
            <output type="ignition.msgs.Twist" topic="/cmd_vel">
                linear: {x: 0.0}, angular: {z: 0.0}
            </output>
        </plugin>


  </world>
</sdf>
